<?xml version="1.0" ?>
<!-- =================================================================================== -->
<!-- |    This document was autogenerated by xacro from raptor_new.sdf                 | -->
<!-- |    EDITING THIS FILE BY HAND IS NOT RECOMMENDED                                 | -->
<!-- =================================================================================== -->
<sdf version="1.6">
  <model name="raptor">
    <!-- Base Link -->
    <link name="base_link">
      <pose>0 0 0 0 0 1.57079632679</pose>
      <inertial>
        <pose>0 0 0 0 0 0</pose>
        <mass>1.5</mass>
        <inertia>
          <ixx>0.029125</ixx>
          <ixy>0</ixy>
          <ixz>0</ixz>
          <iyy>0.029125</iyy>
          <iyz>0</iyz>
          <izz>0.055225</izz>
        </inertia>
      </inertial>
      <self_collide>false</self_collide>
      <collision name="base_link_inertia_collision">
        <pose>0 0 0 0 0 0</pose>
        <geometry>
          <mesh>
            <scale>0.001 0.001 0.001</scale>
            <uri>model://raptor/meshes/drone_hitbox.stl</uri>
          </mesh>
        </geometry>
        <surface>
          <contact>
            <ode>
              <min_depth>0.001</min_depth>
              <max_vel>0</max_vel>
            </ode>
          </contact>
          <friction>
            <friction>
              <ode>
                <mu>100</mu>
                <mu2>50</mu2>
              </ode>
            </friction>
          </friction>
        </surface>
      </collision>
      <visual name="base_link_inertia_visual">
        <pose>0 0 0 0 0 0</pose>
        <geometry>
          <mesh>
            <scale>0.001 0.001 0.001</scale>
            <uri>model://raptor/meshes/drone_w_feets.stl</uri>
          </mesh>
        </geometry>
        <material>
          <script>
            <name>Gazebo/White</name>
            <uri>file://media/materials/scripts/gazebo.material</uri>
          </script>
        </material>
      </visual>
      <gravity>1</gravity>
      <velocity_decay/>
    </link>
    <!-- IMU -->
    <include>
      <uri>model://imu</uri>
      <pose>0 0.03 0 0 0 0</pose>
      <name>imu</name>
    </include>
    <joint name="imu_joint" type="revolute">
      <child>imu::link</child>
      <parent>base_link</parent>
      <axis>
        <xyz>1 0 0</xyz>
        <limit>
          <lower>0</lower>
          <upper>0</upper>
          <effort>0</effort>
          <velocity>0</velocity>
        </limit>
        <dynamics>
          <spring_reference>0</spring_reference>
          <spring_stiffness>0</spring_stiffness>
        </dynamics>
        <use_parent_model_frame>1</use_parent_model_frame>
      </axis>
    </joint>
    <include>
      <uri>model://raptor_rotor</uri>
      <pose>0.13 -0.2 0.023 0 0 0</pose>
      <name>rotor_0</name>
    </include>
    <!-- Rotor Joints -->
    <joint name="rotor_0_joint" type="revolute">
      <child>rotor_0::link</child>
      <parent>base_link</parent>
      <axis>
        <xyz>0 0 1</xyz>
        <limit>
          <lower>-1e+16</lower>
          <upper>1e+16</upper>
        </limit>
        <dynamics>
          <spring_reference>0</spring_reference>
          <spring_stiffness>0</spring_stiffness>
        </dynamics>
        <use_parent_model_frame>1</use_parent_model_frame>
      </axis>
    </joint>
    <!-- Rotor Plugin -->
    <plugin filename="libgazebo_motor_model.so" name="front_right_motor_model">
      <robotNamespace/>
      <jointName>rotor_0_joint</jointName>
      <linkName>rotor_0::link</linkName>
      <turningDirection>ccw</turningDirection>
      <timeConstantUp>0.0125</timeConstantUp>
      <timeConstantDown>0.025</timeConstantDown>
      <maxRotVelocity>1100</maxRotVelocity>
      <motorConstant>5.84e-06</motorConstant>
      <momentConstant>0.06</momentConstant>
      <commandSubTopic>/gazebo/command/motor_speed</commandSubTopic>
      <motorNumber>0</motorNumber>
      <rotorDragCoefficient>0.000175</rotorDragCoefficient>
      <rollingMomentCoefficient>1e-06</rollingMomentCoefficient>
      <motorSpeedPubTopic>/motor_speed/1</motorSpeedPubTopic>
      <rotorVelocitySlowdownSim>10</rotorVelocitySlowdownSim>
    </plugin>
    <include>
      <uri>model://raptor_rotor</uri>
      <pose>-0.13 0.2 0.023 0 0 0</pose>
      <name>rotor_1</name>
    </include>
    <!-- Rotor Joints -->
    <joint name="rotor_1_joint" type="revolute">
      <child>rotor_1::link</child>
      <parent>base_link</parent>
      <axis>
        <xyz>0 0 1</xyz>
        <limit>
          <lower>-1e+16</lower>
          <upper>1e+16</upper>
        </limit>
        <dynamics>
          <spring_reference>0</spring_reference>
          <spring_stiffness>0</spring_stiffness>
        </dynamics>
        <use_parent_model_frame>1</use_parent_model_frame>
      </axis>
    </joint>
    <!-- Rotor Plugin -->
    <plugin filename="libgazebo_motor_model.so" name="back_left_motor_model">
      <robotNamespace/>
      <jointName>rotor_1_joint</jointName>
      <linkName>rotor_1::link</linkName>
      <turningDirection>ccw</turningDirection>
      <timeConstantUp>0.0125</timeConstantUp>
      <timeConstantDown>0.025</timeConstantDown>
      <maxRotVelocity>1100</maxRotVelocity>
      <motorConstant>5.84e-06</motorConstant>
      <momentConstant>0.06</momentConstant>
      <commandSubTopic>/gazebo/command/motor_speed</commandSubTopic>
      <motorNumber>1</motorNumber>
      <rotorDragCoefficient>0.000175</rotorDragCoefficient>
      <rollingMomentCoefficient>1e-06</rollingMomentCoefficient>
      <motorSpeedPubTopic>/motor_speed/1</motorSpeedPubTopic>
      <rotorVelocitySlowdownSim>10</rotorVelocitySlowdownSim>
    </plugin>
    <include>
      <uri>model://raptor_rotor</uri>
      <pose>0.13 0.2 0.023 0 0 0</pose>
      <name>rotor_2</name>
    </include>
    <!-- Rotor Joints -->
    <joint name="rotor_2_joint" type="revolute">
      <child>rotor_2::link</child>
      <parent>base_link</parent>
      <axis>
        <xyz>0 0 1</xyz>
        <limit>
          <lower>-1e+16</lower>
          <upper>1e+16</upper>
        </limit>
        <dynamics>
          <spring_reference>0</spring_reference>
          <spring_stiffness>0</spring_stiffness>
        </dynamics>
        <use_parent_model_frame>1</use_parent_model_frame>
      </axis>
    </joint>
    <!-- Rotor Plugin -->
    <plugin filename="libgazebo_motor_model.so" name="front_left_motor_model">
      <robotNamespace/>
      <jointName>rotor_2_joint</jointName>
      <linkName>rotor_2::link</linkName>
      <turningDirection>cw</turningDirection>
      <timeConstantUp>0.0125</timeConstantUp>
      <timeConstantDown>0.025</timeConstantDown>
      <maxRotVelocity>1100</maxRotVelocity>
      <motorConstant>5.84e-06</motorConstant>
      <momentConstant>0.06</momentConstant>
      <commandSubTopic>/gazebo/command/motor_speed</commandSubTopic>
      <motorNumber>2</motorNumber>
      <rotorDragCoefficient>0.000175</rotorDragCoefficient>
      <rollingMomentCoefficient>1e-06</rollingMomentCoefficient>
      <motorSpeedPubTopic>/motor_speed/1</motorSpeedPubTopic>
      <rotorVelocitySlowdownSim>10</rotorVelocitySlowdownSim>
    </plugin>
    <include>
      <uri>model://raptor_rotor</uri>
      <pose>-0.13 -0.2 0.023 0 0 0</pose>
      <name>rotor_3</name>
    </include>
    <!-- Rotor Joints -->
    <joint name="rotor_3_joint" type="revolute">
      <child>rotor_3::link</child>
      <parent>base_link</parent>
      <axis>
        <xyz>0 0 1</xyz>
        <limit>
          <lower>-1e+16</lower>
          <upper>1e+16</upper>
        </limit>
        <dynamics>
          <spring_reference>0</spring_reference>
          <spring_stiffness>0</spring_stiffness>
        </dynamics>
        <use_parent_model_frame>1</use_parent_model_frame>
      </axis>
    </joint>
    <!-- Rotor Plugin -->
    <plugin filename="libgazebo_motor_model.so" name="back_right_motor_model">
      <robotNamespace/>
      <jointName>rotor_3_joint</jointName>
      <linkName>rotor_3::link</linkName>
      <turningDirection>cw</turningDirection>
      <timeConstantUp>0.0125</timeConstantUp>
      <timeConstantDown>0.025</timeConstantDown>
      <maxRotVelocity>1100</maxRotVelocity>
      <motorConstant>5.84e-06</motorConstant>
      <momentConstant>0.06</momentConstant>
      <commandSubTopic>/gazebo/command/motor_speed</commandSubTopic>
      <motorNumber>3</motorNumber>
      <rotorDragCoefficient>0.000175</rotorDragCoefficient>
      <rollingMomentCoefficient>1e-06</rollingMomentCoefficient>
      <motorSpeedPubTopic>/motor_speed/1</motorSpeedPubTopic>
      <rotorVelocitySlowdownSim>10</rotorVelocitySlowdownSim>
    </plugin>
    <!-- GPS -->
    <include>
      <uri>model://gps</uri>
      <pose> -0.03 0 0 0 0</pose>
      <name>gps0</name>
    </include>
    <joint name="gps0_joint" type="fixed">
      <child>gps0::link</child>
      <parent>base_link</parent>
    </joint>
    <!-- Magnetometer -->
    <include>
      <uri>model://magnetometer</uri>
      <pose>0 0 0 0 0 0</pose>
      <name>mag</name>
    </include>
    <joint name="mag_joint" type="fixed">
      <child>mag::link</child>
      <parent>base_link</parent>
    </joint>
    <!-- Groundtruth -->
    <plugin filename="libgazebo_groundtruth_plugin.so" name="groundtruth_plugin">
      <robotNamespace/>
    </plugin>
    <!-- Barometer -->
    <plugin filename="libgazebo_barometer_plugin.so" name="barometer_plugin">
      <robotNamespace/>
      <pubRate>50</pubRate>
      <baroTopic>/baro</baroTopic>
      <baroDriftPaPerSec>0</baroDriftPaPerSec>
    </plugin>
    <!-- Mavlink -->
    <plugin filename="libgazebo_mavlink_interface.so" name="mavlink_interface">
      <robotNamespace/>
      <imuSubTopic>/imu</imuSubTopic>
      <magSubTopic>/mag</magSubTopic>
      <baroSubTopic>/baro</baroSubTopic>
      <mavlink_addr>INADDR_ANY</mavlink_addr>
      <mavlink_tcp_port>4560</mavlink_tcp_port>
      <mavlink_udp_port>14560</mavlink_udp_port>
      <serialEnabled>0</serialEnabled>
      <serialDevice>/dev/ttyACM0</serialDevice>
      <baudRate>921600</baudRate>
      <qgc_addr>INADDR_ANY</qgc_addr>
      <qgc_udp_port>14550</qgc_udp_port>
      <sdk_addr>INADDR_ANY</sdk_addr>
      <sdk_udp_port>14540</sdk_udp_port>
      <hil_mode>0</hil_mode>
      <hil_state_level>0</hil_state_level>
      <send_vision_estimation>0</send_vision_estimation>
      <send_odometry>1</send_odometry>
      <enable_lockstep>1</enable_lockstep>
      <use_tcp>1</use_tcp>
      <motorSpeedCommandPubTopic>/gazebo/command/motor_speed</motorSpeedCommandPubTopic>
      <control_channels>
        <channel name="rotor1">
          <input_index>0</input_index>
          <input_offset>0</input_offset>
          <input_scaling>1000</input_scaling>
          <zero_position_disarmed>0</zero_position_disarmed>
          <zero_position_armed>100</zero_position_armed>
          <joint_control_type>velocity</joint_control_type>
        </channel>
        <channel name="rotor2">
          <input_index>1</input_index>
          <input_offset>0</input_offset>
          <input_scaling>1000</input_scaling>
          <zero_position_disarmed>0</zero_position_disarmed>
          <zero_position_armed>100</zero_position_armed>
          <joint_control_type>velocity</joint_control_type>
        </channel>
        <channel name="rotor3">
          <input_index>2</input_index>
          <input_offset>0</input_offset>
          <input_scaling>1000</input_scaling>
          <zero_position_disarmed>0</zero_position_disarmed>
          <zero_position_armed>100</zero_position_armed>
          <joint_control_type>velocity</joint_control_type>
        </channel>
        <channel name="rotor4">
          <input_index>3</input_index>
          <input_offset>0</input_offset>
          <input_scaling>1000</input_scaling>
          <zero_position_disarmed>0</zero_position_disarmed>
          <zero_position_armed>100</zero_position_armed>
          <joint_control_type>velocity</joint_control_type>
        </channel>
        <channel name="rotor5">
          <input_index>4</input_index>
          <input_offset>1</input_offset>
          <input_scaling>324.6</input_scaling>
          <zero_position_disarmed>0</zero_position_disarmed>
          <zero_position_armed>0</zero_position_armed>
          <joint_control_type>velocity</joint_control_type>
          <joint_control_pid>
            <p>0.1</p>
            <i>0</i>
            <d>0</d>
            <iMax>0.0</iMax>
            <iMin>0.0</iMin>
            <cmdMax>2</cmdMax>
            <cmdMin>-2</cmdMin>
          </joint_control_pid>
          <joint_name>zephyr_delta_wing::propeller_joint</joint_name>
        </channel>
        <channel name="rotor6">
          <input_index>5</input_index>
          <input_offset>0</input_offset>
          <input_scaling>0.524</input_scaling>
          <zero_position_disarmed>0</zero_position_disarmed>
          <zero_position_armed>0</zero_position_armed>
          <joint_control_type>position</joint_control_type>
          <joint_name>zephyr_delta_wing::flap_left_joint</joint_name>
          <joint_control_pid>
            <d>0</d>
            <iMax>0</iMax>
            <iMin>0</iMin>
            <cmdMax>20</cmdMax>
            <cmdMin>-20</cmdMin>
          </joint_control_pid>
        </channel>
        <channel name="rotor7">
          <input_index>6</input_index>
          <input_offset>0</input_offset>
          <input_scaling>0.524</input_scaling>
          <zero_position_disarmed>0</zero_position_disarmed>
          <zero_position_armed>0</zero_position_armed>
          <joint_control_type>position</joint_control_type>
          <joint_name>zephyr_delta_wing::flap_right_joint</joint_name>
          <joint_control_pid>
            <p>10.0</p>
            <i>0</i>
            <d>0</d>
            <iMax>0</iMax>
            <iMin>0</iMin>
            <cmdMax>20</cmdMax>
            <cmdMin>-20</cmdMin>
          </joint_control_pid>
        </channel>
        <channel name="rotor8">
          <input_index>7</input_index>
          <input_offset>0</input_offset>
          <input_scaling>0.524</input_scaling>
          <zero_position_disarmed>0</zero_position_disarmed>
          <zero_position_armed>0</zero_position_armed>
          <joint_control_type>position</joint_control_type>
        </channel>
      </control_channels>
    </plugin>
    <static>0</static>
    <!-- Gripper -->
    <include>
      <uri>model://raptor_gripper</uri>
      <pose>0 0 -0.05 0 0 0</pose>
      <name>gripper</name>
    </include>
    <joint name="gripper_base_joint" type="fixed">
      <child>gripper::gripper_base_link</child>
      <parent>base_link</parent>
    </joint>
    <plugin filename="libServoPlugin.so" name="gripper_left_plugin">
      <subTopic>leftGripper_deg</subTopic>
      <linkName>gripper::gripper_left_link</linkName>
      <jointName>gripper::gripper_left_joint</jointName>
      <initialAngle>90.0</initialAngle>
      <turningDirection>0</turningDirection>
    </plugin>
    <plugin filename="libServoPlugin.so" name="gripper_right_plugin">
      <subTopic>rightGripper_deg</subTopic>
      <linkName>gripper::gripper_right_link</linkName>
      <jointName>gripper::gripper_right_joint</jointName>
      <initialAngle>90.0</initialAngle>
      <turningDirection>1</turningDirection>
    </plugin>
    <!-- Realsense Cameras -->
    <model name="realsense_camera_front">
      <plugin filename="libRealSensePlugin.so" name="realsense_front_plugin">
        <pubTopic>realsense_front</pubTopic>
      </plugin>
      <include>
        <uri>model://raptor_realsense_front</uri>
        <pose> 0.07 0.0 0 -0.01  0.78539816339 0.0</pose>
        <name>realsense_front</name>
      </include>
      <joint name="realsense_front_joint" type="fixed">
        <child>realsense_front::link</child>
        <parent>base_link</parent>
      </joint>
    </model>
    <model name="realsense_camera_down">
      <plugin filename="libRealSensePlugin.so" name="realsense_down_plugin">
        <pubTopic>realsense_down</pubTopic>
      </plugin>
      <include>
        <uri>model://raptor_realsense_down</uri>
        <pose> 0.0 0.0 -0.08 0.0 1.57079632679 0.0</pose>
        <name>realsense_down</name>
      </include>
      <joint name="realsense_down_joint" type="fixed">
        <child>realsense_down::link</child>
        <parent>base_link</parent>
      </joint>
    </model>
  </model>
</sdf>
